Traceback (most recent call last):
  File "/leonardo/home/userexternal/adivicin/rtdetr/lib/python3.8/site-packages/PIL/Image.py", line 2543, in save
    format = EXTENSION[ext]
KeyError: ''

The above exception was the direct cause of the following exception:

Traceback (most recent call last):
  File "tools/infer.py", line 192, in <module>
    main(args)
  File "tools/infer.py", line 180, in main
    draw([im_pil], args.im_file, labels, boxes, scores, 0.6)
  File "tools/infer.py", line 114, in draw
    im.save(path)
  File "/leonardo/home/userexternal/adivicin/rtdetr/lib/python3.8/site-packages/PIL/Image.py", line 2546, in save
    raise ValueError(msg) from e
ValueError: unknown file extension: 
Traceback (most recent call last):
  File "/leonardo/home/userexternal/adivicin/rtdetr/lib/python3.8/site-packages/PIL/Image.py", line 2543, in save
    format = EXTENSION[ext]
KeyError: ''

The above exception was the direct cause of the following exception:

Traceback (most recent call last):
  File "tools/infer.py", line 192, in <module>
    main(args)
  File "tools/infer.py", line 180, in main
    draw([im_pil], args.im_file, labels, boxes, scores, 0.6)
  File "tools/infer.py", line 114, in draw
    im.save(path)
  File "/leonardo/home/userexternal/adivicin/rtdetr/lib/python3.8/site-packages/PIL/Image.py", line 2546, in save
    raise ValueError(msg) from e
ValueError: unknown file extension: 
